<?xml version="1.0"?>
<robot name="arm">

 <!-- ros_control plugin -->
  <gazebo>
    <plugin name="gazebo_ros_control" filename="libgazebo_ros_control.so">
      <robotNamespace>/asemo_arm</robotNamespace>
      <robotSimType>gazebo_ros_control/DefaultRobotHWSim</robotSimType>
	
	<legacyModeNS>true</legacyModeNS>
    </plugin>
  </gazebo>

<!--bASE lINK/-->
<link name='BASE_link'>

	<visual> 

		<orgin xyz="0 0 0" rpy="0 0 0" />

		<geometry>
		
		<box size="0.05 0.07 0.001"/>

		</geometry>



	</visual>



</link>
<!--shoulder joint/-->
	<joint type="revolute" name="shoulder">
<origin xyz="0 0 0.001" rpy="0 0 0"/>
<limit velocity="1" effort="100" upper="1.57" lower="-1.57"/>
<child link="shoulder_arm"/>
    <parent link="BASE_link"/>
    <axis xyz="0 0 1" rpy="0 0 0"/>


	</joint>

<!-- shoulder_arm link /-->

<link name="shoulder_arm">
    
    
	<visual name="shoulder_arm_visual">
      <origin xyz="0 0 0.02" rpy="0 0 0"/>
      <geometry>
        <box size="0.01 0.001 0.04"/>
      </geometry>
    </visual>
    
  </link>


<!--elbow joint/-->
<joint type="revolute" name="elbow">


	<origin xyz="0 0.002 0.03" rpy="0 0 0"/>
	<limit velocity="1" effort="100" upper="1.57" lower="-1.57"/>
	<child link="elbow_arm"/>
    	<parent link="shoulder_arm"/>
    	<axis xyz="0 1 0" rpy="0 0 0"/>


</joint>


<!-- elbow_arm link /-->

<link name="elbow_arm">
    
    
	<visual name="elbow_arm_visual">
      <origin xyz="0 0 0.02" rpy="0 0 0"/>
      <geometry>
        <box size="0.01 0.001 0.04"/>
      </geometry>
    </visual>
    
  </link>




<!-- gripper joint/-->
<joint type="revolute" name="gripper">


	<origin xyz="0 -0.002 0.03" rpy="0 0 0"/>
	<limit velocity="1" effort="100" upper="1.57" lower="-1.57"/>
	<child link="gripper_arm"/>
    	<parent link="elbow_arm"/>
    	<axis xyz="0 1 0" rpy="0 0 0"/>


</joint>


<!-- gripper_arm link /-->

<link name="gripper_arm">
    
    
	<visual name="gripper_arm_visual">
      <origin xyz="0 0 0.02" rpy="0 0 0"/>
      <geometry>
        <box size="0.01 0.001 0.04"/>
      </geometry>
    </visual>
    
  </link>

<!--  the transmission for ROS control/-->



  <transmission name="shoulder_tran">
    <type>transmission_interface/SimpleTransmission</type>
    <joint name="shoulder">
      <hardwareInterface>hardware_interface/EffortJointInterface</hardwareInterface>
    </joint>
    <actuator name="shoulder_motor">
      <hardwareInterface>hardware_interface/EffortJointInterface</hardwareInterface>
      <mechanicalReduction>1</mechanicalReduction>
    </actuator>
  </transmission>


  <transmission name="elbow_tran">
    <type>transmission_interface/SimpleTransmission</type>
    <joint name="elbow">
      <hardwareInterface>hardware_interface/EffortJointInterface</hardwareInterface>
    </joint>
    <actuator name="elbow_motor">
      <hardwareInterface>hardware_interface/EffortJointInterface</hardwareInterface>
      <mechanicalReduction>1</mechanicalReduction>
    </actuator>
  </transmission>


  <transmission name="gripper_tran">
    <type>transmission_interface/SimpleTransmission</type>
    <joint name="gripper">
      <hardwareInterface>hardware_interface/EffortJointInterface</hardwareInterface>
    </joint>
    <actuator name="gripper_motor">
      <hardwareInterface>hardware_interface/EffortJointInterface</hardwareInterface>
      <mechanicalReduction>1</mechanicalReduction>
    </actuator>
  </transmission>








</robot>
